# 异常处理

## Java的异常

在计算机程序运行的过程中，总是会出现各种各样的错误。

有一些错误是用户造成的，比如，希望用户输入一个`int`类型的年龄，但是用户的输入是`abc`：

```java
// 假设用户输入了abc：
String s = "abc";
int n = Integer.parseInt(s); // NumberFormatException!
```

程序想要读写某个文件的内容，但是用户已经把它删除了：

```java
// 用户删除了该文件：
String t = readFile("C:\\abc.txt"); // FileNotFoundException!
```

还有一些错误是随机出现，并且永远不可能避免的。比如：

- 网络突然断了，连接不到远程服务器；
- 内存耗尽，程序崩溃了；
- 用户点“打印”，但根本没有打印机；
- ……

所以，一个健壮的程序必须处理各种各样的错误。

所谓错误，就是程序调用某个函数的时候，如果失败了，就表示出错。

调用方如何获知调用失败的信息？有两种方法：

方法一：约定返回错误码。

例如，处理一个文件，如果返回`0`，表示成功，返回其他整数，表示约定的错误码：

```java
int code = processFile("C:\\test.txt");
if (code == 0) {
    // ok:
} else {
    // error:
    switch (code) {
    case 1:
        // file not found:
    case 2:
        // no read permission:
    default:
        // unknown error:
    }
}
```

因为使用`int`类型的错误码，想要处理就非常麻烦。这种方式常见于底层C函数。

方法二：在语言层面上提供一个异常处理机制。

Java内置了一套异常处理机制，总是使用异常来表示错误。

异常是一种`class`，因此它本身带有类型信息。异常可以在任何地方抛出，但只需要在上层捕获，这样就和方法调用分离了：

```java
try {
    String s = processFile(“C:\\test.txt”);
    // ok:
} catch (FileNotFoundException e) {
    // file not found:
} catch (SecurityException e) {
    // no read permission:
} catch (IOException e) {
    // io error:
} catch (Exception e) {
    // other error:
}
```

因为Java的异常是`class`，它的继承关系如下：

```ascii
                     ┌───────────┐
                     │  Object   │
                     └───────────┘
                           ▲
                           │
                     ┌───────────┐
                     │ Throwable │
                     └───────────┘
                           ▲
                 ┌─────────┴─────────┐
                 │                   │
           ┌───────────┐       ┌───────────┐
           │   Error   │       │ Exception │
           └───────────┘       └───────────┘
                 ▲                   ▲
         ┌───────┘              ┌────┴──────────┐
         │                      │               │
┌─────────────────┐    ┌─────────────────┐┌───────────┐
│OutOfMemoryError │... │RuntimeException ││IOException│...
└─────────────────┘    └─────────────────┘└───────────┘
                                ▲
                    ┌───────────┴─────────────┐
                    │                         │
         ┌─────────────────────┐ ┌─────────────────────────┐
         │NullPointerException │ │IllegalArgumentException │...
         └─────────────────────┘ └─────────────────────────┘
```

从继承关系可知：`Throwable`是异常体系的根，它继承自`Object`。`Throwable`有两个体系：`Error`和`Exception`，`Error`表示严重的错误，程序对此一般无能为力，例如：

- `OutOfMemoryError`：内存耗尽
- `NoClassDefFoundError`：无法加载某个Class
- `StackOverflowError`：栈溢出

而`Exception`则是运行时的错误，它可以被捕获并处理。

某些异常是应用程序逻辑处理的一部分，应该捕获并处理。例如：

- `NumberFormatException`：数值类型的格式错误
- `FileNotFoundException`：未找到文件
- `SocketException`：读取网络失败

还有一些异常是程序逻辑编写不对造成的，应该修复程序本身。例如：

- `NullPointerException`：对某个`null`的对象调用方法或字段
- `IndexOutOfBoundsException`：数组索引越界

`Exception`又分为两大类：

1. `RuntimeException`以及它的子类；
2. 非`RuntimeException`（包括`IOException`、`ReflectiveOperationException`等等）

Java规定：

- 必须捕获的异常，包括`Exception`及其子类，但不包括`RuntimeException`及其子类，这种类型的异常称为Checked Exception。
- 不需要捕获的异常，包括`Error`及其子类，`RuntimeException`及其子类。

 **注意：编译器对RuntimeException及其子类不做强制捕获要求，不是指应用程序本身不应该捕获并处理RuntimeException。是否需要捕获，具体问题具体分析。**

### 捕获异常

捕获异常使用`try...catch`语句，把可能发生异常的代码放到`try {...}`中，然后使用`catch`捕获对应的`Exception`及其子类：

```java
public class Main {
    public static void main(String[] args) {
        byte[] bs = toGBK("中文");
        System.out.println(Arrays.toString(bs));
    }

    static byte[] toGBK(String s) {
        try {
            // 用指定编码转换String为byte[]:
            return s.getBytes("GBK");
        } catch (UnsupportedEncodingException e) {
            // 如果系统不支持GBK编码，会捕获到UnsupportedEncodingException:
            System.out.println(e); // 打印异常信息
            return s.getBytes(); // 尝试使用用默认编码
        }
    }
}
```

如果我们不捕获`UnsupportedEncodingException`，会出现编译失败的问题：

```java
public class Main {
    public static void main(String[] args) {
        byte[] bs = toGBK("中文");
        System.out.println(Arrays.toString(bs));
    }

    static byte[] toGBK(String s) {
        return s.getBytes("GBK");
    }
}
```

编译器会报错，错误信息类似：unreported exception UnsupportedEncodingException; must be caught or declared to be thrown，并且准确地指出需要捕获的语句是`return s.getBytes("GBK");`。意思是说，像`UnsupportedEncodingException`这样的Checked Exception，必须被捕获。

这是因为`String.getBytes(String)`方法定义是：

```java
public byte[] getBytes(String charsetName) throws UnsupportedEncodingException {
    ...
}
```

在方法定义的时候，使用`throws Xxx`表示该方法可能抛出的异常类型。调用方在调用的时候，必须强制捕获这些异常，否则编译器会报错。

在`toGBK()`方法中，因为调用了`String.getBytes(String)`方法，就必须捕获`UnsupportedEncodingException`。我们也可以不捕获它，而是在方法定义处用throws表示`toGBK()`方法可能会抛出`UnsupportedEncodingException`，就可以让`toGBK()`方法通过编译器检查：

```java
public class Main {
    public static void main(String[] args) {
        byte[] bs = toGBK("中文");
        System.out.println(Arrays.toString(bs));
    }

    static byte[] toGBK(String s) throws UnsupportedEncodingException {
        return s.getBytes("GBK");
    }
}
```

上述代码仍然会得到编译错误，但这一次，编译器提示的不是调用`return s.getBytes("GBK");`的问题，而是`byte[] bs = toGBK("中文");`。因为在`main()`方法中，调用`toGBK()`，没有捕获它声明的可能抛出的`UnsupportedEncodingException`。

修复方法是在`main()`方法中捕获异常并处理：

```java
public class Main {
    public static void main(String[] args) {
        try {
            byte[] bs = toGBK("中文");
            System.out.println(Arrays.toString(bs));
        } catch (UnsupportedEncodingException e) {
            System.out.println(e);
        }
    }

    static byte[] toGBK(String s) throws UnsupportedEncodingException {
        // 用指定编码转换String为byte[]:
        return s.getBytes("GBK");
    }
}
```

可见，只要是方法声明的Checked Exception，不在调用层捕获，也必须在更高的调用层捕获。所有未捕获的异常，最终也必须在`main()`方法中捕获，不会出现漏写`try`的情况。这是由编译器保证的。`main()`方法也是最后捕获`Exception`的机会。

如果是测试代码，上面的写法就略显麻烦。如果不想写任何`try`代码，可以直接把`main()`方法定义为`throws Exception`：

```java
public class Main {
    public static void main(String[] args) throws Exception {
        byte[] bs = toGBK("中文");
        System.out.println(Arrays.toString(bs));
    }

    static byte[] toGBK(String s) throws UnsupportedEncodingException {
        // 用指定编码转换String为byte[]:
        return s.getBytes("GBK");
    }
}
```

因为`main()`方法声明了可能抛出`Exception`，也就声明了可能抛出所有的`Exception`，因此在内部就无需捕获了。代价就是一旦发生异常，程序会立刻退出。

还有一些童鞋喜欢在`toGBK()`内部“消化”异常：

```
static byte[] toGBK(String s) {
    try {
        return s.getBytes("GBK");
    } catch (UnsupportedEncodingException e) {
        // 什么也不干
    }
    return null;
```

这种捕获后不处理的方式是非常不好的，即使真的什么也做不了，也要先把异常记录下来：

```
static byte[] toGBK(String s) {
    try {
        return s.getBytes("GBK");
    } catch (UnsupportedEncodingException e) {
        // 先记下来再说:
        e.printStackTrace();
    }
    return null;
```

所有异常都可以调用`printStackTrace()`方法打印异常栈，这是一个简单有用的快速打印异常的方法。

### 小结

Java使用异常来表示错误，并通过`try ... catch`捕获异常；

Java的异常是`class`，并且从`Throwable`继承；

`Error`是无需捕获的严重错误，`Exception`是应该捕获的可处理的错误；

`RuntimeException`无需强制捕获，非`RuntimeException`（Checked Exception）需强制捕获，或者用`throws`声明；

不推荐捕获了异常但不进行任何处理。

## 捕获异常

在Java中，凡是可能抛出异常的语句，都可以用`try ... catch`捕获。把可能发生异常的语句放在`try { ... }`中，然后使用`catch`捕获对应的`Exception`及其子类。

### 多catch语句

可以使用多个`catch`语句，每个`catch`分别捕获对应的`Exception`及其子类。JVM在捕获到异常后，会从上到下匹配`catch`语句，匹配到某个`catch`后，执行`catch`代码块，然后*不再*继续匹配。

简单地说就是：多个`catch`语句只有一个能被执行。例如：

```java
public static void main(String[] args) {
    try {
        process1();
        process2();
        process3();
    } catch (IOException e) {
        System.out.println(e);
    } catch (NumberFormatException e) {
        System.out.println(e);
    }
}
```

存在多个`catch`的时候，`catch`的顺序非常重要：子类必须写在前面。例如：

```java
public static void main(String[] args) {
    try {
        process1();
        process2();
        process3();
    } catch (IOException e) {
        System.out.println("IO error");
    } catch (UnsupportedEncodingException e) { // 永远捕获不到
        System.out.println("Bad encoding");
    }
}
```

对于上面的代码，`UnsupportedEncodingException`异常是永远捕获不到的，因为它是`IOException`的子类。当抛出`UnsupportedEncodingException`异常时，会被`catch (IOException e) { ... }`捕获并执行。

因此，正确的写法是把子类放到前面：

```java
public static void main(String[] args) {
    try {
        process1();
        process2();
        process3();
    } catch (UnsupportedEncodingException e) {
        System.out.println("Bad encoding");
    } catch (IOException e) {
        System.out.println("IO error");
    }
}
```

### finally语句

无论是否有异常发生，如果我们都希望执行一些语句，例如清理工作，怎么写？

可以把执行语句写若干遍：正常执行的放到`try`中，每个`catch`再写一遍。例如：

```java
public static void main(String[] args) {
    try {
        process1();
        process2();
        process3();
        System.out.println("END");
    } catch (UnsupportedEncodingException e) {
        System.out.println("Bad encoding");
        System.out.println("END");
    } catch (IOException e) {
        System.out.println("IO error");
        System.out.println("END");
    }
}
```

上述代码无论是否发生异常，都会执行`System.out.println("END");`这条语句。

那么如何消除这些重复的代码？Java的`try ... catch`机制还提供了`finally`语句，`finally`语句块保证有无错误都会执行。上述代码可以改写如下：

```java
public static void main(String[] args) {
    try {
        process1();
        process2();
        process3();
    } catch (UnsupportedEncodingException e) {
        System.out.println("Bad encoding");
    } catch (IOException e) {
        System.out.println("IO error");
    } finally {
        System.out.println("END");
    }
}
```

注意`finally`有几个特点：

1. `finally`语句不是必须的，可写可不写；
2. `finally`总是最后执行。

如果没有发生异常，就正常执行`try { ... }`语句块，然后执行`finally`。如果发生了异常，就中断执行`try { ... }`语句块，然后跳转执行匹配的`catch`语句块，最后执行`finally`。

可见，`finally`是用来保证一些代码必须执行的。

某些情况下，可以没有`catch`，只使用`try ... finally`结构。例如：

```java
void process(String file) throws IOException {
    try {
        ...
    } finally {
        System.out.println("END");
    }
}
```

因为方法声明了可能抛出的异常，所以可以不写`catch`。

### 捕获多种异常

如果某些异常的处理逻辑相同，但是异常本身不存在继承关系，那么就得编写多条`catch`子句：

```java
public static void main(String[] args) {
    try {
        process1();
        process2();
        process3();
    } catch (IOException e) {
        System.out.println("Bad input");
    } catch (NumberFormatException e) {
        System.out.println("Bad input");
    } catch (Exception e) {
        System.out.println("Unknown error");
    }
}
```

因为处理`IOException`和`NumberFormatException`的代码是相同的，所以我们可以把它两用`|`合并到一起：

```java
public static void main(String[] args) {
    try {
        process1();
        process2();
        process3();
    } catch (IOException | NumberFormatException e) { // IOException或NumberFormatException
        System.out.println("Bad input");
    } catch (Exception e) {
        System.out.println("Unknown error");
    }
```

### 小结

使用`try ... catch ... finally`时：

- 多个`catch`语句的匹配顺序非常重要，子类必须放在前面；
- `finally`语句保证了有无异常都会执行，它是可选的；
- 一个`catch`语句也可以匹配多个非继承关系的异常。

---

### 异常的传播

当某个方法抛出了异常时，如果当前方法没有捕获异常，异常就会被抛到上层调用方法，直到遇到某个`try ... catch`被捕获为止：

```java
public class Main {
    public static void main(String[] args) {
        try {
            process1();
        } catch (Exception e) {
            e.printStackTrace();
        }
    }

    static void process1() {
        process2();
    }

    static void process2() {
        Integer.parseInt(null); // 会抛出NumberFormatException
    }
}
```

通过`printStackTrace()`可以打印出方法的调用栈，类似：

```
java.lang.NumberFormatException: null
    at java.base/java.lang.Integer.parseInt(Integer.java:614)
    at java.base/java.lang.Integer.parseInt(Integer.java:770)
    at Main.process2(Main.java:16)
    at Main.process1(Main.java:12)
    at Main.main(Main.java:5)
```

`printStackTrace()`对于调试错误非常有用，上述信息表示：`NumberFormatException`是在`java.lang.Integer.parseInt`方法中被抛出的，从下往上看，调用层次依次是：

1. `main()`调用`process1()`；
2. `process1()`调用`process2()`；
3. `process2()`调用`Integer.parseInt(String)`；
4. `Integer.parseInt(String)`调用`Integer.parseInt(String, int)`。

查看`Integer.java`源码可知，抛出异常的方法代码如下：

```
public static int parseInt(String s, int radix) throws NumberFormatException {
    if (s == null) {
        throw new NumberFormatException("null");
    }
    ...
}
```

并且，每层调用均给出了源代码的行号，可直接定位。

### 抛出异常

当发生错误时，例如，用户输入了非法的字符，我们就可以抛出异常。

如何抛出异常？参考`Integer.parseInt()`方法，抛出异常分两步：

1. 创建某个`Exception`的实例；
2. 用`throw`语句抛出。

下面是一个例子：

```java
void process2(String s) {
    if (s==null) {
        NullPointerException e = new NullPointerException();
        throw e;
    }
}
```

实际上，绝大部分抛出异常的代码都会合并写成一行：

```java
void process2(String s) {
    if (s==null) {
        throw new NullPointerException();
    }
}
```

如果一个方法捕获了某个异常后，又在`catch`子句中抛出新的异常，就相当于把抛出的异常类型“转换”了：

```java
void process1(String s) {
    try {
        process2();
    } catch (NullPointerException e) {
        throw new IllegalArgumentException();
    }
}

void process2(String s) {
    if (s==null) {
        throw new NullPointerException();
    }
}
```

当`process2()`抛出`NullPointerException`后，被`process1()`捕获，然后抛出`IllegalArgumentException()`。

如果在`main()`中捕获`IllegalArgumentException`，我们看看打印的异常栈：

```java
public class Main {
    public static void main(String[] args) {
        try {
            process1();
        } catch (Exception e) {
            e.printStackTrace();
        }
    }

    static void process1() {
        try {
            process2();
        } catch (NullPointerException e) {
            throw new IllegalArgumentException();
        }
    }

    static void process2() {
        throw new NullPointerException();
    }
}
```

